error 
Data (trigger: interval[0:00:02], next run at: 2018-03-30 10:47:37 CST)" raised an exception
Traceback (most recent call last):
  File "C:\Users\Administrator\AppData\Local\Programs\Python\Python36\lib\urllib\request.py", line 1318, in do_open
    encode_chunked=req.has_header('Transfer-encoding'))
  File "C:\Users\Administrator\AppData\Local\Programs\Python\Python36\lib\http\client.py", line 1239, in request
    self._send_request(method, url, body, headers, encode_chunked)
  File "C:\Users\Administrator\AppData\Local\Programs\Python\Python36\lib\http\client.py", line 1285, in _send_request
    self.endheaders(body, encode_chunked=encode_chunked)
  File "C:\Users\Administrator\AppData\Local\Programs\Python\Python36\lib\http\client.py", line 1234, in endheaders
    self._send_output(message_body, encode_chunked=encode_chunked)
  File "C:\Users\Administrator\AppData\Local\Programs\Python\Python36\lib\http\client.py", line 1026, in _send_output
    self.send(msg)
  File "C:\Users\Administrator\AppData\Local\Programs\Python\Python36\lib\http\client.py", line 964, in send
    self.connect()
  File "C:\Users\Administrator\AppData\Local\Programs\Python\Python36\lib\http\client.py", line 936, in connect
    (self.host,self.port), self.timeout, self.source_address)
  File "C:\Users\Administrator\AppData\Local\Programs\Python\Python36\lib\socket.py", line 724, in create_connection
    raise err
  File "C:\Users\Administrator\AppData\Local\Programs\Python\Python36\lib\socket.py", line 713, in create_connection
    sock.connect(sa)
socket.timeout: timed out

During handling of the above exception, another exception occurred:

Traceback (most recent call last):
  File "C:\Users\Administrator\AppData\Local\Programs\Python\Python36\lib\site-packages\apscheduler\executors\base.py", line 125, in run_job
    retval = job.func(*job.args, **job.kwargs)
  File "C:\aqua\stocking\stock\src\tools\T10.py", line 133, in getData
    df = ts.get_realtime_quotes(codeSplitMaps[key])
  File "C:\Users\Administrator\AppData\Local\Programs\Python\Python36\lib\site-packages\tushare\stock\trading.py", line 371, in get_realtime_quotes
    text = urlopen(request,timeout=10).read()
  File "C:\Users\Administrator\AppData\Local\Programs\Python\Python36\lib\urllib\request.py", line 223, in urlopen
    return opener.open(url, data, timeout)
  File "C:\Users\Administrator\AppData\Local\Programs\Python\Python36\lib\urllib\request.py", line 526, in open
    response = self._open(req, data)
  File "C:\Users\Administrator\AppData\Local\Programs\Python\Python36\lib\urllib\request.py", line 544, in _open
    '_open', req)
  File "C:\Users\Administrator\AppData\Local\Programs\Python\Python36\lib\urllib\request.py", line 504, in _call_chain
    result = func(*args)
  File "C:\Users\Administrator\AppData\Local\Programs\Python\Python36\lib\urllib\request.py", line 1346, in http_open
    return self.do_open(http.client.HTTPConnection, req)
  File "C:\Users\Administrator\AppData\Local\Programs\Python\Python36\lib\urllib\request.py", line 1320, in do_open
    raise URLError(err)
urllib.error.URLError: <urlopen error timed out>
Job "getData (trigger: interval[0:00:02], next run at: 2018-03-30 10:50:29 CST)" raised an exception
Traceback (most recent call last):
  File "C:\Users\Administrator\AppData\Local\Programs\Python\Python36\lib\urllib\request.py", line 1318, in do_open
    encode_chunked=req.has_header('Transfer-encoding'))
  File "C:\Users\Administrator\AppData\Local\Programs\Python\Python36\lib\http\client.py", line 1239, in request
    self._send_request(method, url, body, headers, encode_chunked)
  File "C:\Users\Administrator\AppData\Local\Programs\Python\Python36\lib\http\client.py", line 1285, in _send_request
    self.endheaders(body, encode_chunked=encode_chunked)
  File "C:\Users\Administrator\AppData\Local\Programs\Python\Python36\lib\http\client.py", line 1234, in endheaders
    self._send_output(message_body, encode_chunked=encode_chunked)
  File "C:\Users\Administrator\AppData\Local\Programs\Python\Python36\lib\http\client.py", line 1026, in _send_output
    self.send(msg)
  File "C:\Users\Administrator\AppData\Local\Programs\Python\Python36\lib\http\client.py", line 964, in send
    self.connect()
  File "C:\Users\Administrator\AppData\Local\Programs\Python\Python36\lib\http\client.py", line 936, in connect
    (self.host,self.port), self.timeout, self.source_address)
  File "C:\Users\Administrator\AppData\Local\Programs\Python\Python36\lib\socket.py", line 724, in create_connection
    raise err
  File "C:\Users\Administrator\AppData\Local\Programs\Python\Python36\lib\socket.py", line 713, in create_connection
    sock.connect(sa)
socket.timeout: timed out

During handling of the above exception, another exception occurred:

Traceback (most recent call last):
  File "C:\Users\Administrator\AppData\Local\Programs\Python\Python36\lib\site-packages\apscheduler\executors\base.py", line 125, in run_job
    retval = job.func(*job.args, **job.kwargs)
  File "C:\aqua\stocking\stock\src\tools\T10.py", line 133, in getData
    df = ts.get_realtime_quotes(codeSplitMaps[key])
  File "C:\Users\Administrator\AppData\Local\Programs\Python\Python36\lib\site-packages\tushare\stock\trading.py", line 371, in get_realtime_quotes
    text = urlopen(request,timeout=10).read()
  File "C:\Users\Administrator\AppData\Local\Programs\Python\Python36\lib\urllib\request.py", line 223, in urlopen
    return opener.open(url, data, timeout)
  File "C:\Users\Administrator\AppData\Local\Programs\Python\Python36\lib\urllib\request.py", line 526, in open
    response = self._open(req, data)
  File "C:\Users\Administrator\AppData\Local\Programs\Python\Python36\lib\urllib\request.py", line 544, in _open
    '_open', req)
  File "C:\Users\Administrator\AppData\Local\Programs\Python\Python36\lib\urllib\request.py", line 504, in _call_chain
    result = func(*args)
  File "C:\Users\Administrator\AppData\Local\Programs\Python\Python36\lib\urllib\request.py", line 1346, in http_open
    return self.do_open(http.client.HTTPConnection, req)
  File "C:\Users\Administrator\AppData\Local\Programs\Python\Python36\lib\urllib\request.py", line 1320, in do_open
    raise URLError(err)
urllib.error.URLError: <urlopen error timed out>
Job "getData (trigger: interval[0:00:02], next run at: 2018-03-30 10:50:45 CST)" raised an exception
Traceback (most recent call last):
  File "C:\Users\Administrator\AppData\Local\Programs\Python\Python36\lib\urllib\request.py", line 1318, in do_open
    encode_chunked=req.has_header('Transfer-encoding'))
  File "C:\Users\Administrator\AppData\Local\Programs\Python\Python36\lib\http\client.py", line 1239, in request
    self._send_request(method, url, body, headers, encode_chunked)
  File "C:\Users\Administrator\AppData\Local\Programs\Python\Python36\lib\http\client.py", line 1285, in _send_request
    self.endheaders(body, encode_chunked=encode_chunked)
  File "C:\Users\Administrator\AppData\Local\Programs\Python\Python36\lib\http\client.py", line 1234, in endheaders
    self._send_output(message_body, encode_chunked=encode_chunked)
  File "C:\Users\Administrator\AppData\Local\Programs\Python\Python36\lib\http\client.py", line 1026, in _send_output
    self.send(msg)
  File "C:\Users\Administrator\AppData\Local\Programs\Python\Python36\lib\http\client.py", line 964, in send
    self.connect()
  File "C:\Users\Administrator\AppData\Local\Programs\Python\Python36\lib\http\client.py", line 936, in connect
    (self.host,self.port), self.timeout, self.source_address)
  File "C:\Users\Administrator\AppData\Local\Programs\Python\Python36\lib\socket.py", line 704, in create_connection
    for res in getaddrinfo(host, port, 0, SOCK_STREAM):
  File "C:\Users\Administrator\AppData\Local\Programs\Python\Python36\lib\socket.py", line 745, in getaddrinfo
    for res in _socket.getaddrinfo(host, port, family, type, proto, flags):
socket.gaierror: [Errno 11004] getaddrinfo failed

During handling of the above exception, another exception occurred:

Traceback (most recent call last):
  File "C:\Users\Administrator\AppData\Local\Programs\Python\Python36\lib\site-packages\apscheduler\executors\base.py", line 125, in run_job
    retval = job.func(*job.args, **job.kwargs)
  File "C:\aqua\stocking\stock\src\tools\T10.py", line 133, in getData
    df = ts.get_realtime_quotes(codeSplitMaps[key])
  File "C:\Users\Administrator\AppData\Local\Programs\Python\Python36\lib\site-packages\tushare\stock\trading.py", line 371, in get_realtime_quotes
    text = urlopen(request,timeout=10).read()
  File "C:\Users\Administrator\AppData\Local\Programs\Python\Python36\lib\urllib\request.py", line 223, in urlopen
    return opener.open(url, data, timeout)
  File "C:\Users\Administrator\AppData\Local\Programs\Python\Python36\lib\urllib\request.py", line 526, in open
    response = self._open(req, data)
  File "C:\Users\Administrator\AppData\Local\Programs\Python\Python36\lib\urllib\request.py", line 544, in _open
    '_open', req)
  File "C:\Users\Administrator\AppData\Local\Programs\Python\Python36\lib\urllib\request.py", line 504, in _call_chain
    result = func(*args)
  File "C:\Users\Administrator\AppData\Local\Programs\Python\Python36\lib\urllib\request.py", line 1346, in http_open
    return self.do_open(http.client.HTTPConnection, req)
  File "C:\Users\Administrator\AppData\Local\Programs\Python\Python36\lib\urllib\request.py", line 1320, in do_open
    raise URLError(err)
urllib.error.URLError: <urlopen error [Errno 11004] getaddrinfo failed>
Job "getData (trigger: interval[0:00:02], next run at: 2018-03-30 10:55:55 CST)" raised an exception
Traceback (most recent call last):
  File "C:\Users\Administrator\AppData\Local\Programs\Python\Python36\lib\urllib\request.py", line 1318, in do_open
    encode_chunked=req.has_header('Transfer-encoding'))
  File "C:\Users\Administrator\AppData\Local\Programs\Python\Python36\lib\http\client.py", line 1239, in request
    self._send_request(method, url, body, headers, encode_chunked)
  File "C:\Users\Administrator\AppData\Local\Programs\Python\Python36\lib\http\client.py", line 1285, in _send_request
    self.endheaders(body, encode_chunked=encode_chunked)
  File "C:\Users\Administrator\AppData\Local\Programs\Python\Python36\lib\http\client.py", line 1234, in endheaders
    self._send_output(message_body, encode_chunked=encode_chunked)
  File "C:\Users\Administrator\AppData\Local\Programs\Python\Python36\lib\http\client.py", line 1026, in _send_output
    self.send(msg)
  File "C:\Users\Administrator\AppData\Local\Programs\Python\Python36\lib\http\client.py", line 964, in send
    self.connect()
  File "C:\Users\Administrator\AppData\Local\Programs\Python\Python36\lib\http\client.py", line 936, in connect
    (self.host,self.port), self.timeout, self.source_address)
  File "C:\Users\Administrator\AppData\Local\Programs\Python\Python36\lib\socket.py", line 724, in create_connection
    raise err
  File "C:\Users\Administrator\AppData\Local\Programs\Python\Python36\lib\socket.py", line 713, in create_connection
    sock.connect(sa)
socket.timeout: timed out

During handling of the above exception, another exception occurred:

Traceback (most recent call last):
  File "C:\Users\Administrator\AppData\Local\Programs\Python\Python36\lib\site-packages\apscheduler\executors\base.py", line 125, in run_job
    retval = job.func(*job.args, **job.kwargs)
  File "C:\aqua\stocking\stock\src\tools\T10.py", line 133, in getData
    df = ts.get_realtime_quotes(codeSplitMaps[key])
  File "C:\Users\Administrator\AppData\Local\Programs\Python\Python36\lib\site-packages\tushare\stock\trading.py", line 371, in get_realtime_quotes
    text = urlopen(request,timeout=10).read()
  File "C:\Users\Administrator\AppData\Local\Programs\Python\Python36\lib\urllib\request.py", line 223, in urlopen
    return opener.open(url, data, timeout)
  File "C:\Users\Administrator\AppData\Local\Programs\Python\Python36\lib\urllib\request.py", line 526, in open
    response = self._open(req, data)
  File "C:\Users\Administrator\AppData\Local\Programs\Python\Python36\lib\urllib\request.py", line 544, in _open
    '_open', req)
  File "C:\Users\Administrator\AppData\Local\Programs\Python\Python36\lib\urllib\request.py", line 504, in _call_chain
    result = func(*args)
  File "C:\Users\Administrator\AppData\Local\Programs\Python\Python36\lib\urllib\request.py", line 1346, in http_open
    return self.do_open(http.client.HTTPConnection, req)
  File "C:\Users\Administrator\AppData\Local\Programs\Python\Python36\lib\urllib\request.py", line 1320, in do_open
    raise URLError(err)
urllib.error.URLError: <urlopen error timed out>
Job "getData (trigger: interval[0:00:02], next run at: 2018-03-30 15:34:45 CST)" raised an exception
Traceback (most recent call last):
  File "C:\Users\Administrator\AppData\Local\Programs\Python\Python36\lib\urllib\request.py", line 1318, in do_open
    encode_chunked=req.has_header('Transfer-encoding'))
  File "C:\Users\Administrator\AppData\Local\Programs\Python\Python36\lib\http\client.py", line 1239, in request
    self._send_request(method, url, body, headers, encode_chunked)
  File "C:\Users\Administrator\AppData\Local\Programs\Python\Python36\lib\http\client.py", line 1285, in _send_request
    self.endheaders(body, encode_chunked=encode_chunked)
  File "C:\Users\Administrator\AppData\Local\Programs\Python\Python36\lib\http\client.py", line 1234, in endheaders
    self._send_output(message_body, encode_chunked=encode_chunked)
  File "C:\Users\Administrator\AppData\Local\Programs\Python\Python36\lib\http\client.py", line 1026, in _send_output
    self.send(msg)
  File "C:\Users\Administrator\AppData\Local\Programs\Python\Python36\lib\http\client.py", line 964, in send
    self.connect()
  File "C:\Users\Administrator\AppData\Local\Programs\Python\Python36\lib\http\client.py", line 936, in connect
    (self.host,self.port), self.timeout, self.source_address)
  File "C:\Users\Administrator\AppData\Local\Programs\Python\Python36\lib\socket.py", line 724, in create_connection
    raise err
  File "C:\Users\Administrator\AppData\Local\Programs\Python\Python36\lib\socket.py", line 713, in create_connection
    sock.connect(sa)
socket.timeout: timed out

During handling of the above exception, another exception occurred:

Traceback (most recent call last):
  File "C:\Users\Administrator\AppData\Local\Programs\Python\Python36\lib\site-packages\apscheduler\executors\base.py", line 125, in run_job
    retval = job.func(*job.args, **job.kwargs)
  File "C:\aqua\stocking\stock\src\tools\T10.py", line 133, in getData
    df = ts.get_realtime_quotes(codeSplitMaps[key])
  File "C:\Users\Administrator\AppData\Local\Programs\Python\Python36\lib\site-packages\tushare\stock\trading.py", line 371, in get_realtime_quotes
    text = urlopen(request,timeout=10).read()
  File "C:\Users\Administrator\AppData\Local\Programs\Python\Python36\lib\urllib\request.py", line 223, in urlopen
    return opener.open(url, data, timeout)
  File "C:\Users\Administrator\AppData\Local\Programs\Python\Python36\lib\urllib\request.py", line 526, in open
    response = self._open(req, data)
  File "C:\Users\Administrator\AppData\Local\Programs\Python\Python36\lib\urllib\request.py", line 544, in _open
    '_open', req)
  File "C:\Users\Administrator\AppData\Local\Programs\Python\Python36\lib\urllib\request.py", line 504, in _call_chain
    result = func(*args)
  File "C:\Users\Administrator\AppData\Local\Programs\Python\Python36\lib\urllib\request.py", line 1346, in http_open
    return self.do_open(http.client.HTTPConnection, req)
  File "C:\Users\Administrator\AppData\Local\Programs\Python\Python36\lib\urllib\request.py", line 1320, in do_open
    raise URLError(err)
urllib.error.URLError: <urlopen error timed out>
Job "getData (trigger: interval[0:00:02], next run at: 2018-03-30 15:35:01 CST)" raised an exception
Traceback (most recent call last):
  File "C:\Users\Administrator\AppData\Local\Programs\Python\Python36\lib\urllib\request.py", line 1318, in do_open
    encode_chunked=req.has_header('Transfer-encoding'))
  File "C:\Users\Administrator\AppData\Local\Programs\Python\Python36\lib\http\client.py", line 1239, in request
    self._send_request(method, url, body, headers, encode_chunked)
  File "C:\Users\Administrator\AppData\Local\Programs\Python\Python36\lib\http\client.py", line 1285, in _send_request
    self.endheaders(body, encode_chunked=encode_chunked)
  File "C:\Users\Administrator\AppData\Local\Programs\Python\Python36\lib\http\client.py", line 1234, in endheaders
    self._send_output(message_body, encode_chunked=encode_chunked)
  File "C:\Users\Administrator\AppData\Local\Programs\Python\Python36\lib\http\client.py", line 1026, in _send_output
    self.send(msg)
  File "C:\Users\Administrator\AppData\Local\Programs\Python\Python36\lib\http\client.py", line 964, in send
    self.connect()
  File "C:\Users\Administrator\AppData\Local\Programs\Python\Python36\lib\http\client.py", line 936, in connect
    (self.host,self.port), self.timeout, self.source_address)
  File "C:\Users\Administrator\AppData\Local\Programs\Python\Python36\lib\socket.py", line 704, in create_connection
    for res in getaddrinfo(host, port, 0, SOCK_STREAM):
  File "C:\Users\Administrator\AppData\Local\Programs\Python\Python36\lib\socket.py", line 745, in getaddrinfo
    for res in _socket.getaddrinfo(host, port, family, type, proto, flags):
socket.gaierror: [Errno 11004] getaddrinfo failed

During handling of the above exception, another exception occurred:

Traceback (most recent call last):
  File "C:\Users\Administrator\AppData\Local\Programs\Python\Python36\lib\site-packages\apscheduler\executors\base.py", line 125, in run_job
    retval = job.func(*job.args, **job.kwargs)
  File "C:\aqua\stocking\stock\src\tools\T10.py", line 133, in getData
    df = ts.get_realtime_quotes(codeSplitMaps[key])
  File "C:\Users\Administrator\AppData\Local\Programs\Python\Python36\lib\site-packages\tushare\stock\trading.py", line 371, in get_realtime_quotes
    text = urlopen(request,timeout=10).read()
  File "C:\Users\Administrator\AppData\Local\Programs\Python\Python36\lib\urllib\request.py", line 223, in urlopen
    return opener.open(url, data, timeout)
  File "C:\Users\Administrator\AppData\Local\Programs\Python\Python36\lib\urllib\request.py", line 526, in open
    response = self._open(req, data)
  File "C:\Users\Administrator\AppData\Local\Programs\Python\Python36\lib\urllib\request.py", line 544, in _open
    '_open', req)
  File "C:\Users\Administrator\AppData\Local\Programs\Python\Python36\lib\urllib\request.py", line 504, in _call_chain
    result = func(*args)
  File "C:\Users\Administrator\AppData\Local\Programs\Python\Python36\lib\urllib\request.py", line 1346, in http_open
    return self.do_open(http.client.HTTPConnection, req)
  File "C:\Users\Administrator\AppData\Local\Programs\Python\Python36\lib\urllib\request.py", line 1320, in do_open
    raise URLError(err)
urllib.error.URLError: <urlopen error [Errno 11004] getaddrinfo failed>
Job "getData (trigger: interval[0:00:02], next run at: 2018-03-30 15:35:17 CST)" raised an exception
Traceback (most recent call last):
  File "C:\Users\Administrator\AppData\Local\Programs\Python\Python36\lib\urllib\request.py", line 1318, in do_open
    encode_chunked=req.has_header('Transfer-encoding'))
  File "C:\Users\Administrator\AppData\Local\Programs\Python\Python36\lib\http\client.py", line 1239, in request
    self._send_request(method, url, body, headers, encode_chunked)
  File "C:\Users\Administrator\AppData\Local\Programs\Python\Python36\lib\http\client.py", line 1285, in _send_request
    self.endheaders(body, encode_chunked=encode_chunked)
  File "C:\Users\Administrator\AppData\Local\Programs\Python\Python36\lib\http\client.py", line 1234, in endheaders
    self._send_output(message_body, encode_chunked=encode_chunked)
  File "C:\Users\Administrator\AppData\Local\Programs\Python\Python36\lib\http\client.py", line 1026, in _send_output
    self.send(msg)
  File "C:\Users\Administrator\AppData\Local\Programs\Python\Python36\lib\http\client.py", line 964, in send
    self.connect()
  File "C:\Users\Administrator\AppData\Local\Programs\Python\Python36\lib\http\client.py", line 936, in connect
    (self.host,self.port), self.timeout, self.source_address)
  File "C:\Users\Administrator\AppData\Local\Programs\Python\Python36\lib\socket.py", line 704, in create_connection
    for res in getaddrinfo(host, port, 0, SOCK_STREAM):
  File "C:\Users\Administrator\AppData\Local\Programs\Python\Python36\lib\socket.py", line 745, in getaddrinfo
    for res in _socket.getaddrinfo(host, port, family, type, proto, flags):
socket.gaierror: [Errno 11004] getaddrinfo failed

During handling of the above exception, another exception occurred:

Traceback (most recent call last):
  File "C:\Users\Administrator\AppData\Local\Programs\Python\Python36\lib\site-packages\apscheduler\executors\base.py", line 125, in run_job
    retval = job.func(*job.args, **job.kwargs)
  File "C:\aqua\stocking\stock\src\tools\T10.py", line 133, in getData
    df = ts.get_realtime_quotes(codeSplitMaps[key])
  File "C:\Users\Administrator\AppData\Local\Programs\Python\Python36\lib\site-packages\tushare\stock\trading.py", line 371, in get_realtime_quotes
    text = urlopen(request,timeout=10).read()
  File "C:\Users\Administrator\AppData\Local\Programs\Python\Python36\lib\urllib\request.py", line 223, in urlopen
    return opener.open(url, data, timeout)
  File "C:\Users\Administrator\AppData\Local\Programs\Python\Python36\lib\urllib\request.py", line 526, in open
    response = self._open(req, data)
  File "C:\Users\Administrator\AppData\Local\Programs\Python\Python36\lib\urllib\request.py", line 544, in _open
    '_open', req)
  File "C:\Users\Administrator\AppData\Local\Programs\Python\Python36\lib\urllib\request.py", line 504, in _call_chain
    result = func(*args)
  File "C:\Users\Administrator\AppData\Local\Programs\Python\Python36\lib\urllib\request.py", line 1346, in http_open
    return self.do_open(http.client.HTTPConnection, req)
  File "C:\Users\Administrator\AppData\Local\Programs\Python\Python36\lib\urllib\request.py", line 1320, in do_open
    raise URLError(err)
urllib.error.URLError: <urlopen error [Errno 11004] getaddrinfo failed>
Job "getData (trigger: interval[0:00:02], next run at: 2018-03-30 15:45:15 CST)" raised an exception
Traceback (most recent call last):
  File "C:\Users\Administrator\AppData\Local\Programs\Python\Python36\lib\urllib\request.py", line 1318, in do_open
    encode_chunked=req.has_header('Transfer-encoding'))
  File "C:\Users\Administrator\AppData\Local\Programs\Python\Python36\lib\http\client.py", line 1239, in request
    self._send_request(method, url, body, headers, encode_chunked)
  File "C:\Users\Administrator\AppData\Local\Programs\Python\Python36\lib\http\client.py", line 1285, in _send_request
    self.endheaders(body, encode_chunked=encode_chunked)
  File "C:\Users\Administrator\AppData\Local\Programs\Python\Python36\lib\http\client.py", line 1234, in endheaders
    self._send_output(message_body, encode_chunked=encode_chunked)
  File "C:\Users\Administrator\AppData\Local\Programs\Python\Python36\lib\http\client.py", line 1026, in _send_output
    self.send(msg)
  File "C:\Users\Administrator\AppData\Local\Programs\Python\Python36\lib\http\client.py", line 964, in send
    self.connect()
  File "C:\Users\Administrator\AppData\Local\Programs\Python\Python36\lib\http\client.py", line 936, in connect
    (self.host,self.port), self.timeout, self.source_address)
  File "C:\Users\Administrator\AppData\Local\Programs\Python\Python36\lib\socket.py", line 724, in create_connection
    raise err
  File "C:\Users\Administrator\AppData\Local\Programs\Python\Python36\lib\socket.py", line 713, in create_connection
    sock.connect(sa)
socket.timeout: timed out

During handling of the above exception, another exception occurred:

Traceback (most recent call last):
  File "C:\Users\Administrator\AppData\Local\Programs\Python\Python36\lib\site-packages\apscheduler\executors\base.py", line 125, in run_job
    retval = job.func(*job.args, **job.kwargs)
  File "C:\aqua\stocking\stock\src\tools\T10.py", line 133, in getData
    df = ts.get_realtime_quotes(codeSplitMaps[key])
  File "C:\Users\Administrator\AppData\Local\Programs\Python\Python36\lib\site-packages\tushare\stock\trading.py", line 371, in get_realtime_quotes
    text = urlopen(request,timeout=10).read()
  File "C:\Users\Administrator\AppData\Local\Programs\Python\Python36\lib\urllib\request.py", line 223, in urlopen
    return opener.open(url, data, timeout)
  File "C:\Users\Administrator\AppData\Local\Programs\Python\Python36\lib\urllib\request.py", line 526, in open
    response = self._open(req, data)
  File "C:\Users\Administrator\AppData\Local\Programs\Python\Python36\lib\urllib\request.py", line 544, in _open
    '_open', req)
  File "C:\Users\Administrator\AppData\Local\Programs\Python\Python36\lib\urllib\request.py", line 504, in _call_chain
    result = func(*args)
  File "C:\Users\Administrator\AppData\Local\Programs\Python\Python36\lib\urllib\request.py", line 1346, in http_open
    return self.do_open(http.client.HTTPConnection, req)
  File "C:\Users\Administrator\AppData\Local\Programs\Python\Python36\lib\urllib\request.py", line 1320, in do_open
    raise URLError(err)
urllib.error.URLError: <urlopen error timed out>
Job "getData (trigger: interval[0:00:02], next run at: 2018-03-30 15:45:49 CST)" raised an exception
Traceback (most recent call last):
  File "C:\Users\Administrator\AppData\Local\Programs\Python\Python36\lib\urllib\request.py", line 1318, in do_open
    encode_chunked=req.has_header('Transfer-encoding'))
  File "C:\Users\Administrator\AppData\Local\Programs\Python\Python36\lib\http\client.py", line 1239, in request
    self._send_request(method, url, body, headers, encode_chunked)
  File "C:\Users\Administrator\AppData\Local\Programs\Python\Python36\lib\http\client.py", line 1285, in _send_request
    self.endheaders(body, encode_chunked=encode_chunked)
  File "C:\Users\Administrator\AppData\Local\Programs\Python\Python36\lib\http\client.py", line 1234, in endheaders
    self._send_output(message_body, encode_chunked=encode_chunked)
  File "C:\Users\Administrator\AppData\Local\Programs\Python\Python36\lib\http\client.py", line 1026, in _send_output
    self.send(msg)
  File "C:\Users\Administrator\AppData\Local\Programs\Python\Python36\lib\http\client.py", line 964, in send
    self.connect()
  File "C:\Users\Administrator\AppData\Local\Programs\Python\Python36\lib\http\client.py", line 936, in connect
    (self.host,self.port), self.timeout, self.source_address)
  File "C:\Users\Administrator\AppData\Local\Programs\Python\Python36\lib\socket.py", line 724, in create_connection
    raise err
  File "C:\Users\Administrator\AppData\Local\Programs\Python\Python36\lib\socket.py", line 713, in create_connection
    sock.connect(sa)
socket.timeout: timed out

During handling of the above exception, another exception occurred:

Traceback (most recent call last):
  File "C:\Users\Administrator\AppData\Local\Programs\Python\Python36\lib\site-packages\apscheduler\executors\base.py", line 125, in run_job
    retval = job.func(*job.args, **job.kwargs)
  File "C:\aqua\stocking\stock\src\tools\T10.py", line 134, in getData
    zs = ts.get_realtime_quotes(['sh','sz','hs300','sz50','zxb','cyb'])
  File "C:\Users\Administrator\AppData\Local\Programs\Python\Python36\lib\site-packages\tushare\stock\trading.py", line 371, in get_realtime_quotes
    text = urlopen(request,timeout=10).read()
  File "C:\Users\Administrator\AppData\Local\Programs\Python\Python36\lib\urllib\request.py", line 223, in urlopen
    return opener.open(url, data, timeout)
  File "C:\Users\Administrator\AppData\Local\Programs\Python\Python36\lib\urllib\request.py", line 526, in open
    response = self._open(req, data)
  File "C:\Users\Administrator\AppData\Local\Programs\Python\Python36\lib\urllib\request.py", line 544, in _open
    '_open', req)
  File "C:\Users\Administrator\AppData\Local\Programs\Python\Python36\lib\urllib\request.py", line 504, in _call_chain
    result = func(*args)
  File "C:\Users\Administrator\AppData\Local\Programs\Python\Python36\lib\urllib\request.py", line 1346, in http_open
    return self.do_open(http.client.HTTPConnection, req)
  File "C:\Users\Administrator\AppData\Local\Programs\Python\Python36\lib\urllib\request.py", line 1320, in do_open
    raise URLError(err)
urllib.error.URLError: <urlopen error timed out>
Job "getData (trigger: interval[0:00:02], next run at: 2018-03-30 15:49:21 CST)" raised an exception
Traceback (most recent call last):
  File "C:\Users\Administrator\AppData\Local\Programs\Python\Python36\lib\site-packages\apscheduler\executors\base.py", line 125, in run_job
    retval = job.func(*job.args, **job.kwargs)
  File "C:\aqua\stocking\stock\src\tools\T10.py", line 134, in getData
    zs = ts.get_realtime_quotes(['sh','sz','hs300','sz50','zxb','cyb'])
  File "C:\Users\Administrator\AppData\Local\Programs\Python\Python36\lib\site-packages\tushare\stock\trading.py", line 371, in get_realtime_quotes
    text = urlopen(request,timeout=10).read()
  File "C:\Users\Administrator\AppData\Local\Programs\Python\Python36\lib\urllib\request.py", line 223, in urlopen
    return opener.open(url, data, timeout)
  File "C:\Users\Administrator\AppData\Local\Programs\Python\Python36\lib\urllib\request.py", line 526, in open
    response = self._open(req, data)
  File "C:\Users\Administrator\AppData\Local\Programs\Python\Python36\lib\urllib\request.py", line 544, in _open
    '_open', req)
  File "C:\Users\Administrator\AppData\Local\Programs\Python\Python36\lib\urllib\request.py", line 504, in _call_chain
    result = func(*args)
  File "C:\Users\Administrator\AppData\Local\Programs\Python\Python36\lib\urllib\request.py", line 1346, in http_open
    return self.do_open(http.client.HTTPConnection, req)
  File "C:\Users\Administrator\AppData\Local\Programs\Python\Python36\lib\urllib\request.py", line 1321, in do_open
    r = h.getresponse()
  File "C:\Users\Administrator\AppData\Local\Programs\Python\Python36\lib\http\client.py", line 1331, in getresponse
    response.begin()
  File "C:\Users\Administrator\AppData\Local\Programs\Python\Python36\lib\http\client.py", line 297, in begin
    version, status, reason = self._read_status()
  File "C:\Users\Administrator\AppData\Local\Programs\Python\Python36\lib\http\client.py", line 258, in _read_status
    line = str(self.fp.readline(_MAXLINE + 1), "iso-8859-1")
  File "C:\Users\Administrator\AppData\Local\Programs\Python\Python36\lib\socket.py", line 586, in readinto
    return self._sock.recv_into(b)
socket.timeout: timed out
