child process 1852 is running
[300526] reach 10 save data
[300589] reach 10 save data
[002438] reach 10 save data
[000908] reach 10 save data
[002112] reach 10 save data
[002931] reach 10 save data
[002886] reach 10 save data
[002890] reach 10 save data
[002900] reach 10 save data
 '603223', '603177', '603168', '603161', '603129', '603118', '603110', '603099', '603069', '603063', '603060', '603058', '603028', '601882', '601500', '601116', '601086', '600981', '600865', '600853', '600838', '600833', '600825', '600800', '600721', '600716', '600689', '600653', '600647', '600634', '600602', '600594', '600571', '600560', '600520', '600517', '600462', '600456', '600422', '600419', '600400', '600387', '600386', '600360', '600354', '600343', '600303', '600281', '600272', '600268', '600215', '600213', '600207', '600206', '600192', '600187', '600184', '600178', '600131', '600117', '600113', '600099', '600095', '600088', '300735', '300733', '300731', '300730', '300723', '300720', '300719', '300717', '300716', '300715', '300711', '300708', '300705', '300702', '300686', '300682', '300680', '300675', '300664', '300612', '300611', '300609', '300606', '300593', '300590', '300589', '300582', '300579', '300576', '300565', '300562', '300556', '300555', '300552', '300550', '300548', '300546', '300542', '300530', '300526', '300522', '300519', '300509', '300500', '300496', '300494', '300490', '300479', '300477', '300469', '300428', '300427', '300412', '300403', '300402', '300399', '300398', '300363', '300352', '300349', '300346', '300345', '300339', '300334', '300331', '300322', '300302', '300298', '300293', '300268', '300265', '300263', '300259', '300252', '300249', '300235', '300223', '300220', '300216', '300205', '300189', '300188', '300175', '300161', '300150', '300140', '300134', '300123', '300117', '300114', '300107', '300105', '300100', '300093', '300078', '300065', '300034', '300020', '300010', '002931', '002923', '002922', '002921', '002919', '002911', '002909', '002900', '002890', '002886', '002858', '002848', '002845', '002830', '002826', '002824', '002822', '002816', '002815', '002808', '002806', '002786', '002782', '002777', '002771', '002748', '002742', '002738', '002722', '002715', '002702', '002694', '002667', '002666', '002642', '002632', '002625', '002621', '002618', '002605', '002587', '002577', '002570', '002569', '002568', '002566', '002523', '002510', '002476', '002461', '002455', '002438', '002417', '002367', '002365', '002361', '002346', '002339', '002297', '002265', '002264', '002208', '002190', '002173', '002164', '002151', '002137', '002133', '002112', '002066', '002046', '002045', '002026', '002017', '002016', '000993', '000985', '000971', '000925', '000917', '000909', '000908', '000893', '000851', '000820', '000819', '000810', '000801', '000790', '000789', '000788', '000759', '000713', '000695', '000687', '000670', '000615', '000605', '000572', '000565', '000532', '000416', '000301', '000153', '000065', '000037', '000032', '000023', '000019', '000014', '600962']
calc stocks size 300
Adding job tentatively -- it will be properly scheduled when the scheduler starts
Added job "getData" to job store "default"
Scheduler started
Job "getData (trigger: interval[0:00:02], next run at: 2018-04-07 09:48:18 CST)" raised an exception
Traceback (most recent call last):
  File "C:\Users\Administrator\AppData\Local\Programs\Python\Python36-32\lib\urllib\request.py", line 1318, in do_open
    encode_chunked=req.has_header('Transfer-encoding'))
  File "C:\Users\Administrator\AppData\Local\Programs\Python\Python36-32\lib\http\client.py", line 1239, in request
    self._send_request(method, url, body, headers, encode_chunked)
  File "C:\Users\Administrator\AppData\Local\Programs\Python\Python36-32\lib\http\client.py", line 1285, in _send_request
    self.endheaders(body, encode_chunked=encode_chunked)
  File "C:\Users\Administrator\AppData\Local\Programs\Python\Python36-32\lib\http\client.py", line 1234, in endheaders
    self._send_output(message_body, encode_chunked=encode_chunked)
  File "C:\Users\Administrator\AppData\Local\Programs\Python\Python36-32\lib\http\client.py", line 1026, in _send_output
    self.send(msg)
  File "C:\Users\Administrator\AppData\Local\Programs\Python\Python36-32\lib\http\client.py", line 964, in send
    self.connect()
  File "C:\Users\Administrator\AppData\Local\Programs\Python\Python36-32\lib\http\client.py", line 936, in connect
    (self.host,self.port), self.timeout, self.source_address)
  File "C:\Users\Administrator\AppData\Local\Programs\Python\Python36-32\lib\socket.py", line 724, in create_connection
    raise err
  File "C:\Users\Administrator\AppData\Local\Programs\Python\Python36-32\lib\socket.py", line 713, in create_connection
    sock.connect(sa)
socket.timeout: timed out

During handling of the above exception, another exception occurred:

Traceback (most recent call last):
  File "C:\Users\Administrator\AppData\Local\Programs\Python\Python36-32\lib\site-packages\apscheduler\executors\base.py", line 125, in run_job
    retval = job.func(*job.args, **job.kwargs)
  File "C:\aqua\stock\stocking\src\tools\T10.py", line 132, in getData
    df = ts.get_realtime_quotes(codeSplitMaps[key])
  File "C:\Users\Administrator\AppData\Local\Programs\Python\Python36-32\lib\site-packages\tushare\stock\trading.py", line 371, in get_realtime_quotes
    text = urlopen(request,timeout=10).read()
  File "C:\Users\Administrator\AppData\Local\Programs\Python\Python36-32\lib\urllib\request.py", line 223, in urlopen
    return opener.open(url, data, timeout)
  File "C:\Users\Administrator\AppData\Local\Programs\Python\Python36-32\lib\urllib\request.py", line 526, in open
    response = self._open(req, data)
  File "C:\Users\Administrator\AppData\Local\Programs\Python\Python36-32\lib\urllib\request.py", line 544, in _open
    '_open', req)
  File "C:\Users\Administrator\AppData\Local\Programs\Python\Python36-32\lib\urllib\request.py", line 504, in _call_chain
    result = func(*args)
  File "C:\Users\Administrator\AppData\Local\Programs\Python\Python36-32\lib\urllib\request.py", line 1346, in http_open
    return self.do_open(http.client.HTTPConnection, req)
  File "C:\Users\Administrator\AppData\Local\Programs\Python\Python36-32\lib\urllib\request.py", line 1320, in do_open
    raise URLError(err)
urllib.error.URLError: <urlopen error timed out>
Job "getData (trigger: interval[0:00:02], next run at: 2018-04-07 09:48:22 CST)" raised an exception
Traceback (most recent call last):
  File "C:\Users\Administrator\AppData\Local\Programs\Python\Python36-32\lib\site-packages\apscheduler\executors\base.py", line 125, in run_job
    retval = job.func(*job.args, **job.kwargs)
  File "C:\aqua\stock\stocking\src\tools\T10.py", line 132, in getData
    df = ts.get_realtime_quotes(codeSplitMaps[key])
  File "C:\Users\Administrator\AppData\Local\Programs\Python\Python36-32\lib\site-packages\tushare\stock\trading.py", line 371, in get_realtime_quotes
    text = urlopen(request,timeout=10).read()
  File "C:\Users\Administrator\AppData\Local\Programs\Python\Python36-32\lib\http\client.py", line 462, in read
    s = self._safe_read(self.length)
  File "C:\Users\Administrator\AppData\Local\Programs\Python\Python36-32\lib\http\client.py", line 612, in _safe_read
    chunk = self.fp.read(min(amt, MAXAMOUNT))
  File "C:\Users\Administrator\AppData\Local\Programs\Python\Python36-32\lib\socket.py", line 586, in readinto
    return self._sock.recv_into(b)
socket.timeout: timed out
Job "getData (trigger: interval[0:00:02], next run at: 2018-04-07 09:48:32 CST)" raised an exception
Traceback (most recent call last):
  File "C:\Users\Administrator\AppData\Local\Programs\Python\Python36-32\lib\urllib\request.py", line 1318, in do_open
    encode_chunked=req.has_header('Transfer-encoding'))
  File "C:\Users\Administrator\AppData\Local\Programs\Python\Python36-32\lib\http\client.py", line 1239, in request
    self._send_request(method, url, body, headers, encode_chunked)
  File "C:\Users\Administrator\AppData\Local\Programs\Python\Python36-32\lib\http\client.py", line 1285, in _send_request
    self.endheaders(body, encode_chunked=encode_chunked)
  File "C:\Users\Administrator\AppData\Local\Programs\Python\Python36-32\lib\http\client.py", line 1234, in endheaders
    self._send_output(message_body, encode_chunked=encode_chunked)
  File "C:\Users\Administrator\AppData\Local\Programs\Python\Python36-32\lib\http\client.py", line 1026, in _send_output
    self.send(msg)
  File "C:\Users\Administrator\AppData\Local\Programs\Python\Python36-32\lib\http\client.py", line 964, in send
    self.connect()
  File "C:\Users\Administrator\AppData\Local\Programs\Python\Python36-32\lib\http\client.py", line 936, in connect
    (self.host,self.port), self.timeout, self.source_address)
  File "C:\Users\Administrator\AppData\Local\Programs\Python\Python36-32\lib\socket.py", line 724, in create_connection
    raise err
  File "C:\Users\Administrator\AppData\Local\Programs\Python\Python36-32\lib\socket.py", line 713, in create_connection
    sock.connect(sa)
socket.timeout: timed out

During handling of the above exception, another exception occurred:

Traceback (most recent call last):
  File "C:\Users\Administrator\AppData\Local\Programs\Python\Python36-32\lib\site-packages\apscheduler\executors\base.py", line 125, in run_job
    retval = job.func(*job.args, **job.kwargs)
  File "C:\aqua\stock\stocking\src\tools\T10.py", line 132, in getData
    df = ts.get_realtime_quotes(codeSplitMaps[key])
  File "C:\Users\Administrator\AppData\Local\Programs\Python\Python36-32\lib\site-packages\tushare\stock\trading.py", line 371, in get_realtime_quotes
    text = urlopen(request,timeout=10).read()
  File "C:\Users\Administrator\AppData\Local\Programs\Python\Python36-32\lib\urllib\request.py", line 223, in urlopen
    return opener.open(url, data, timeout)
  File "C:\Users\Administrator\AppData\Local\Programs\Python\Python36-32\lib\urllib\request.py", line 526, in open
    response = self._open(req, data)
  File "C:\Users\Administrator\AppData\Local\Programs\Python\Python36-32\lib\urllib\request.py", line 544, in _open
    '_open', req)
  File "C:\Users\Administrator\AppData\Local\Programs\Python\Python36-32\lib\urllib\request.py", line 504, in _call_chain
    result = func(*args)
  File "C:\Users\Administrator\AppData\Local\Programs\Python\Python36-32\lib\urllib\request.py", line 1346, in http_open
    return self.do_open(http.client.HTTPConnection, req)
  File "C:\Users\Administrator\AppData\Local\Programs\Python\Python36-32\lib\urllib\request.py", line 1320, in do_open
    raise URLError(err)
urllib.error.URLError: <urlopen error timed out>
Job "getData (trigger: interval[0:00:02], next run at: 2018-04-07 09:49:04 CST)" raised an exception
Traceback (most recent call last):
  File "C:\Users\Administrator\AppData\Local\Programs\Python\Python36-32\lib\site-packages\apscheduler\executors\base.py", line 125, in run_job
    retval = job.func(*job.args, **job.kwargs)
  File "C:\aqua\stock\stocking\src\tools\T10.py", line 135, in getData
    queueMaps[key].put({'zs' : zs, 'df' : df,'hygn' : interDataHolder['hygn'],'netMoney' : interDataHolder['netMoney']})
  File "<string>", line 2, in put
  File "C:\Users\Administrator\AppData\Local\Programs\Python\Python36-32\lib\multiprocessing\managers.py", line 756, in _callmethod
    conn.send((self._id, methodname, args, kwds))
  File "C:\Users\Administrator\AppData\Local\Programs\Python\Python36-32\lib\multiprocessing\connection.py", line 206, in send
    self._send_bytes(_ForkingPickler.dumps(obj))
  File "C:\Users\Administrator\AppData\Local\Programs\Python\Python36-32\lib\multiprocessing\connection.py", line 280, in _send_bytes
    ov, err = _winapi.WriteFile(self._handle, buf, overlapped=True)
BrokenPipeError: [WinError 232] 管道正在被关闭。
Job "getData (trigger: interval[0:00:02], next run at: 2018-04-07 09:49:04 CST)" raised an exception
Traceback (most recent call last):
  File "C:\Users\Administrator\AppData\Local\Programs\Python\Python36-32\lib\site-packages\apscheduler\executors\base.py", line 125, in run_job
    retval = job.func(*job.args, **job.kwargs)
  File "C:\aqua\stock\stocking\src\tools\T10.py", line 135, in getData
    queueMaps[key].put({'zs' : zs, 'df' : df,'hygn' : interDataHolder['hygn'],'netMoney' : interDataHolder['netMoney']})
  File "<string>", line 2, in put
  File "C:\Users\Administrator\AppData\Local\Programs\Python\Python36-32\lib\multiprocessing\managers.py", line 756, in _callmethod
    conn.send((self._id, methodname, args, kwds))
  File "C:\Users\Administrator\AppData\Local\Programs\Python\Python36-32\lib\multiprocessing\connection.py", line 206, in send
    self._send_bytes(_ForkingPickler.dumps(obj))
  File "C:\Users\Administrator\AppData\Local\Programs\Python\Python36-32\lib\multiprocessing\connection.py", line 280, in _send_bytes
    ov, err = _winapi.WriteFile(self._handle, buf, overlapped=True)
BrokenPipeError: [WinError 232] 管道正在被关闭。
Job "getData (trigger: interval[0:00:02], next run at: 2018-04-07 09:49:04 CST)" raised an exception
Traceback (most recent call last):
  File "C:\Users\Administrator\AppData\Local\Programs\Python\Python36-32\lib\site-packages\apscheduler\executors\base.py", line 125, in run_job
    retval = job.func(*job.args, **job.kwargs)
  File "C:\aqua\stock\stocking\src\tools\T10.py", line 135, in getData
    queueMaps[key].put({'zs' : zs, 'df' : df,'hygn' : interDataHolder['hygn'],'netMoney' : interDataHolder['netMoney']})
  File "<string>", line 2, in put
  File "C:\Users\Administrator\AppData\Local\Programs\Python\Python36-32\lib\multiprocessing\managers.py", line 756, in _callmethod
    conn.send((self._id, methodname, args, kwds))
  File "C:\Users\Administrator\AppData\Local\Programs\Python\Python36-32\lib\multiprocessing\connection.py", line 206, in send
    self._send_bytes(_ForkingPickler.dumps(obj))
  File "C:\Users\Administrator\AppData\Local\Programs\Python\Python36-32\lib\multiprocessing\connection.py", line 280, in _send_bytes
    ov, err = _winapi.WriteFile(self._handle, buf, overlapped=True)
BrokenPipeError: [WinError 232] 管道正在被关闭。
Job "getData (trigger: interval[0:00:02], next run at: 2018-04-07 09:49:04 CST)" raised an exception
Traceback (most recent call last):
  File "C:\Users\Administrator\AppData\Local\Programs\Python\Python36-32\lib\site-packages\apscheduler\executors\base.py", line 125, in run_job
    retval = job.func(*job.args, **job.kwargs)
  File "C:\aqua\stock\stocking\src\tools\T10.py", line 132, in getData
    df = ts.get_realtime_quotes(codeSplitMaps[key])
  File "C:\Users\Administrator\AppData\Local\Programs\Python\Python36-32\lib\site-packages\tushare\stock\trading.py", line 371, in get_realtime_quotes
    text = urlopen(request,timeout=10).read()
  File "C:\Users\Administrator\AppData\Local\Programs\Python\Python36-32\lib\http\client.py", line 462, in read
    s = self._safe_read(self.length)
  File "C:\Users\Administrator\AppData\Local\Programs\Python\Python36-32\lib\http\client.py", line 612, in _safe_read
    chunk = self.fp.read(min(amt, MAXAMOUNT))
  File "C:\Users\Administrator\AppData\Local\Programs\Python\Python36-32\lib\socket.py", line 586, in readinto
    return self._sock.recv_into(b)
socket.timeout: timed out
Job "getData (trigger: interval[0:00:02], next run at: 2018-04-07 09:49:04 CST)" raised an exception
Traceback (most recent call last):
  File "C:\Users\Administrator\AppData\Local\Programs\Python\Python36-32\lib\site-packages\apscheduler\executors\base.py", line 125, in run_job
    retval = job.func(*job.args, **job.kwargs)
  File "C:\aqua\stock\stocking\src\tools\T10.py", line 132, in getData
    df = ts.get_realtime_quotes(codeSplitMaps[key])
  File "C:\Users\Administrator\AppData\Local\Programs\Python\Python36-32\lib\site-packages\tushare\stock\trading.py", line 371, in get_realtime_quotes
    text = urlopen(request,timeout=10).read()
  File "C:\Users\Administrator\AppData\Local\Programs\Python\Python36-32\lib\http\client.py", line 462, in read
    s = self._safe_read(self.length)
  File "C:\Users\Administrator\AppData\Local\Programs\Python\Python36-32\lib\http\client.py", line 612, in _safe_read
    chunk = self.fp.read(min(amt, MAXAMOUNT))
  File "C:\Users\Administrator\AppData\Local\Programs\Python\Python36-32\lib\socket.py", line 586, in readinto
    return self._sock.recv_into(b)
socket.timeout: timed out
