Job "getData (trigger: interval[0:00:02], next run at: 2018-03-01 13:21:32 CST)" raised an exception
Traceback (most recent call last):
  File "D:\Python35\lib\site-packages\apscheduler\executors\base.py", line 125, in run_job
    retval = job.func(*job.args, **job.kwargs)
  File "D:\aqua\stock\stocking\src\tools\T10.py", line 142, in getData
    queueMaps[key].put({'df' : df,'hygn' : interDataHolder['hygn'],'netMoney' : interDataHolder['netMoney']})
  File "<string>", line 2, in put
  File "D:\Python35\lib\multiprocessing\managers.py", line 716, in _callmethod
    conn.send((self._id, methodname, args, kwds))
  File "D:\Python35\lib\multiprocessing\connection.py", line 206, in send
    self._send_bytes(ForkingPickler.dumps(obj))
  File "D:\Python35\lib\multiprocessing\connection.py", line 280, in _send_bytes
    ov, err = _winapi.WriteFile(self._handle, buf, overlapped=True)
BrokenPipeError: [WinError 232] The pipe is being closed
